Workbook
Name Slicer_Destination: #N/A

Sheet Dashboard
D1: Apex DRP - Control Tower de Distribución
D2: Cargas Ineficientes | F2: FEFO en Riesgo | H2: Envíos Fantasma | J2: Huérfanas
D3: =Excepciones!B2 -> 361 | F3: =Excepciones!B3 -> 45 | H3: =Excepciones!B4 -> 51 | J3: =Excepciones!B5 -> 12
A4: Estado de Carga | B4: Órdenes
A5: CARGA INEFICIENTE | B5: 361
A6: n/a | B6: 12
A7: OK | B7: 732
A8: Grand Total | B8: 1105
A21: Row Labels | B21: Count of FEFO_Flag
A22: FEFO RIESGO | B22: 45
A23: n/a | B23: 12
A24: OK | B24: 1048
A25: Grand Total | B25: 1105

Sheet Transit_Enriched
A1: Order_ID | B1: Origin | C1: Destination | D1: Item_Code | E1: Quantity | F1: Dispatch_Date | G1: SAP_Status | H1: Qty_Quality | I1: Weight_kg | J1: Units_Per_Pallet | K1: Shelf_Life_Days | L1: Match_Status | M1: Dias_En_Transito
A2: SO-50312 | B2: PL-SUR | C2: CD-MER | D2: LAC-1013 | E2: 2260 | F2: 46173 | G2: In Transit | H2: OK | I2: 8.32 | J2: 98 | K2: 16 | L2: OK | M2: 4
A3: SO-50335 | B3: PL-NTE | C3: CD-HER | D3: LAC-1013 | E3: 2769 | F3: 46175 | G3: Delivered | H3: OK | I3: 8.32 | J3: 98 | K3: 16 | L3: OK | M3: 2
A4: SO-50334 | B4: PL-NTE | C4: CD-SAL | D4: ABA-1008 | E4: 2157 | F4: 46175 | G4: In Transit | H4: OK | I4: 10.6 | J4: 96 | K4: 445 | L4: OK | M4: 2
A5: SO-50098 | B5: PL-CEN | C5: CD-VER | D5: ABA-1008 | E5: 2130 | F5: 46174 | G5: In Transit | H5: OK | I5: 10.6 | J5: 96 | K5: 445 | L5: OK | M5: 3
A6: SO-50626 | B6: PL-SUR | C6: CD-LEO | D6: BOT-1001 | E6: 1998 | F6: 46175 | G6: Delivered | H6: OK | I6: 6.95 | J6: 66 | K6: 95 | L6: OK | M6: 2
A7: SO-51098 | B7: PL-CEN | C7: CD-TOL | D7: BOT-1001 | E7: 2091 | F7: 46170 | G7: In Transit | H7: OK | I7: 6.95 | J7: 66 | K7: 95 | L7: OK | M7: 7
A8: SO-51025 | B8: PL-SUR | C8: CD-CAN | D8: LAC-1003 | E8: 2320 | F8: 46162 | G8: In Transit | H8: OK | I8: 9.02 | J8: 114 | K8: 18 | L8: OK | M8: 15
A9: SO-50981 | B9: PL-SUR | C9: CD-GDL | D9: LAC-1003 | E9: 2296 | F9: 46176 | G9: In Transit | H9: OK | I9: 9.02 | J9: 114 | K9: 18 | L9: OK | M9: 1
A10: SO-50240 | B10: PL-CEN | C10: CD-PUE | D10: BOT-1009 | E10: 997 | F10: 46176 | G10: In Transit | H10: OK | I10: 5.25 | J10: 76 | K10: 104 | L10: OK | M10: 1
A11: SO-50101 | B11: PL-CEN | C11: CD-TOL | D11: BOT-1011 | E11: 2534 | F11: 46176 | G11: In Transit | H11: OK | I11: 3.43 | J11: 88 | K11: 109 | L11: OK | M11: 1
A12: SO-50596 | B12: PL-CEN | C12: CD-QRO | D12: BOT-1011 | E12: 2712 | F12: 46175 | G12: In Transit | H12: OK | I12: 3.43 | J12: 88 | K12: 109 | L12: OK | M12: 2
A13: SO-50083 | B13: PL-CEN | C13: CD-VER | D13: BEB-1005 | E13: 901 | F13: 46176 | G13: In Transit | H13: OK | I13: 14.2 | J13: 95 | K13: 277 | L13: OK | M13: 1
... A94: SO-51034 | B94: PL-NTE | C94: CD-MTY | D94: LAC-1008 | E94: 2025 | F94: 46165 | G94: In Transit | H94: OK | I94: 9.8 | J94: 83 | K94: 15 | L94: OK | M94: 12
A95: SO-50205 | B95: PL-CEN | C95: CD-TOL | D95: BEB-1016 | E95: 826 | F95: 46176 | G95: In Transit | H95: OK | J95: 98 | K95: 359 | L95: OK | M95: 1
A96: SO-50968 | B96: PL-NTE | C96: CD-HER | D96: PRO-1006 | E96: 1859 | F96: 46174 | G96: In Transit | H96: OK | I96: 12.09 | J96: 80 | K96: 138 | L96: OK | M96: 3
A97: SO-50890 | B97: PL-CEN | C97: CD-TOL | D97: PRO-1006 | E97: 1899 | F97: 46176 | G97: In Transit | H97: OK | I97: 12.09 | J97: 80 | K97: 138 | L97: OK | M97: 1
A98: SO-50591 | B98: PL-SUR | C98: CD-CAN | D98: LAC-1012 | E98: 609 | F98: 46173 | G98: In Transit | H98: OK | I98: 9.87 | J98: 88 | K98: 25 | L98: OK | M98: 4
A99: SO-50484 | B99: PL-NTE | C99: CD-SAL | D99: BEB-1007 | E99: 1491 | F99: 46176 | G99: In Transit | H99: OK | I99: 13.67 | J99: 78 | K99: 247 | L99: OK | M99: 1
A100: SO-50860 | B100: PL-CEN | C100: CD-CDMX | D100: PRO-1015 | E100: 3302 | F100: 46176 | G100: In Transit | H100: OK | I100: 6.16 | J100: 104 | K100: 67 | L100: OK | M100: 1
A101: SO-51069 | B101: PL-SUR | C101: CD-LEO | D101: ABA-1010 | E101: 2523 | F101: 46174 | G101: In Transit | H101: OK | I101: 8.75 | J101: 123 | K101: 341 | L101: OK | M101: 3
A102: SO-50712 | B102: PL-NTE | C102: CD-TIJ | D102: ABA-1019 | E102: 1279 | F102: 46173 | G102: In Transit | H102: OK | I102: 14.82 | J102: 132 | K102: 373 | L102: OK | M102: 4
A103: SO-50254 | B103: PL-SUR | C103: CD-GDL | D103: ABA-1003 | E103: 2461 | F103: 46176 | G103: In Transit | H103: OK | I103: 8.67 | J103: 124 | K103: 512 | L103: OK | M103: 1
A104: SO-50231 | B104: PL-NTE | C104: CD-CHI | D104: BEB-1003 | E104: 1039 | F104: 46175 | G104: In Transit | H104: OK | I104: 20.5 | J104: 64 | K104: 359 | L104: OK | M104: 2
A105: SO-51011 | B105: PL-SUR | C105: CD-LEO | D105: LAC-1005 | E105: 2399 | F105: 46166 | G105: In Transit | H105: OK | I105: 8.94 | J105: 100 | K105: 17 | L105: OK | M105: 11
A106: SO-50137 | B106: PL-CEN | C106: CD-TOL | D106: BEB-1004 | E106: 450 | F106: 46176 | G106: In Transit | H106: OK | I106: 21.99 | J106: 67 | K106: 213 | L106: OK | M106: 1
A107: SO-50767 | B107: PL-CEN | C107: CD-PUE | D107: ABA-1003 | E107: 943 | F107: 46176 | G107: In Transit | H107: OK | I107: 8.67 | J107: 124 | K107: 512 | L107: OK | M107: 1
... A152: SO-50732 | B152: PL-CEN | C152: CD-QRO | D152: BOT-1008 | E152: 1798 | F152: 46176 | G152: In Transit | H152: OK | I152: 3.48 | J152: 66 | K152: 112 | L152: OK | M152: 1
A153: SO-50633 | B153: PL-NTE | C153: CD-CHI | D153: BOT-1007 | E153: 3645 | F153: 46175 | G153: In Transit | H153: OK | J153: 49 | K153: 104 | L153: OK | M153: 2
A154: SO-50944 | B154: PL-SUR | C154: CD-LEO | D154: BOT-1013 | E154: 1536 | F154: 46176 | G154: In Transit | H154: OK | I154: 4 | J154: 58 | K154: 112 | L154: OK | M154: 1
A155: SO-50053 | B155: PL-SUR | C155: CD-MER | D155: BOT-1008 | E155: 1736 | F155: 46174 | G155: Delivered | H155: OK | I155: 3.48 | J155: 66 | K155: 112 | L155: OK | M155: 3
A156: SO-50018 | B156: PL-NTE | C156: CD-MTY | D156: BEB-1009 | E156: 1198 | F156: 46176 | G156: In Transit | H156: OK | I156: 18.17 | J156: 61 | K156: 188 | L156: OK | M156: 1
A157: SO-50029 | B157: PL-CEN | C157: CD-VER | D157: LAC-1014 | E157: 1147 | F157: 46175 | G157: In Transit | H157: OK | I157: 8.05 | J157: 147 | K157: 28 | L157: OK | M157: 2
A158: SO-50572 | B158: PL-SUR | C158: CD-LEO | D158: ABA-1005 | E158: 1646 | F158: 46175 | G158: In Transit | H158: OK | I158: 13.31 | J158: 89 | K158: 313 | L158: OK | M158: 2
A159: SO-50586 | B159: PL-NTE | C159: CD-MTY | D159: BEB-1016 | E159: 415 | F159: 46176 | G159: In Transit | H159: OK | J159: 98 | K159: 359 | L159: OK | M159: 1
A160: SO-50422 | B160: PL-SUR | C160: CD-LEO | D160: ABA-1003 | E160: 2305 | F160: 46176 | G160: In Transit | H160: OK | I160: 8.67 | J160: 124 | K160: 512 | L160: OK | M160: 1
A161: SO-50072 | B161: PL-CEN | C161: CD-VER | D161: LAC-1015 | E161: 1235 | F161: 46175 | G161: In Transit | H161: OK | I161: 11.26 | J161: 129 | K161: 24 | L161: OK | M161: 2
A162: SO-50159 | B162: PL-SUR | C162: CD-MER | D162: PRO-1010 | E162: 2215 | F162: 46176 | G162: In Transit | H162: OK | I162: 7.76 | J162: 86 | K162: 112 | L162: OK | M162: 1
A163: SO-50864 | B163: PL-SUR | C163: CD-LEO | D163: ABA-1015 | E163: 1030 | F163: 46175 | G163: In Transit | H163: OK | I163: 8.19 | J163: 82 | K163: 317 | L163: OK | M163: 2
A164: SO-50847 | B164: PL-NTE | C164: CD-TIJ | D164: BOT-1021 | E164: 709 | F164: 46176 | G164: In Transit | H164: OK | I164: 5.04 | J164: 47 | K164: 96 | L164: OK | M164: 1
...

Sheet Analisis_Transito
A1: {=Transit_Enriched[#All]} -> Order_ID | B1: Origin | C1: Destination | D1: Item_Code | E1: Quantity | F1: Dispatch_Date | G1: SAP_Status | H1: Qty_Quality | I1: Weight_kg | J1: Units_Per_Pallet | K1: Shelf_Life_Days | L1: Match_Status | M1: Dias_En_Transito | O1: Pallets_Used | P1: Fill_Weight_% | Q1: Fill_Pallet_% | R1: Camiones | S1: Eficiencia_% | T1: Carga_Flag | U1: FEFO_Flag | V1: Fantasma_Flag
A2: SO-50312 | B2: PL-SUR | C2: CD-MER | D2: LAC-1013 | E2: 2260 | F2: 46173 | G2: In Transit | H2: OK | I2: 8.32 | J2: 98 | K2: 16 | L2: OK | M2: 4 | O2: =IF(L2="HUERFANO","n/a",IF(ISNUMBER(J2),E2/J2,"n/a")) -> 23.061224 | P2: =IF(L2="HUERFANO","n/a",IFERROR(E2*I2/24000*100,"")) -> 78.346667 | Q2: =IF(L2="HUERFANO","n/a",IFERROR(O2/33*100,"")) -> 69.882498 | R2: =IF(L2="HUERFANO","n/a",IFERROR(MAX(CEILING(P2/100,1),CEILING(Q2/100,1)),"")) -> 1 | S2: =IF(L2="HUERFANO","n/a",IFERROR(MAX(P2,Q2)/(R2*100)*100,"")) -> 78.346667 | T2: =IF(L2="HUERFANO","n/a",IF(S2<75,"CARGA INEFICIENTE","OK")) -> OK | U2: =IF(L2="HUERFANO","n/a",IF(AND(LEFT(D2,3)="LAC",(K2-M2)/K2*100<70),"FEFO RIESGO","OK")) -> OK | V2: =IF(L2="HUERFANO","n/a",IF(AND(G2="In Transit",M2>5),"FANTASMA","OK")) -> OK
A3: SO-50335 | B3: PL-NTE | C3: CD-HER | D3: LAC-1013 | E3: 2769 | F3: 46175 | G3: Delivered | H3: OK | I3: 8.32 | J3: 98 | K3: 16 | L3: OK | M3: 2 | O3: =IF(L3="HUERFANO","n/a",IF(ISNUMBER(J3),E3/J3,"n/a")) -> 28.255102 | P3: =IF(L3="HUERFANO","n/a",IFERROR(E3*I3/24000*100,"")) -> 95.992 | Q3: =IF(L3="HUERFANO","n/a",IFERROR(O3/33*100,"")) -> 85.621521 | R3: =IF(L3="HUERFANO","n/a",IFERROR(MAX(CEILING(P3/100,1),CEILING(Q3/100,1)),"")) -> 1 | S3: =IF(L3="HUERFANO","n/a",IFERROR(MAX(P3,Q3)/(R3*100)*100,"")) -> 95.992 | T3: =IF(L3="HUERFANO","n/a",IF(S3<75,"CARGA INEFICIENTE","OK")) -> OK | U3: =IF(L3="HUERFANO","n/a",IF(AND(LEFT(D3,3)="LAC",(K3-M3)/K3*100<70),"FEFO RIESGO","OK")) -> OK | V3: =IF(L3="HUERFANO","n/a",IF(AND(G3="In Transit",M3>5),"FANTASMA","OK")) -> OK
A4: SO-50334 | B4: PL-NTE | C4: CD-SAL | D4: ABA-1008 | E4: 2157 | F4: 46175 | G4: In Transit | H4: OK | I4: 10.6 | J4: 96 | K4: 445 | L4: OK | M4: 2 | O4: =IF(L4="HUERFANO","n/a",IF(ISNUMBER(J4),E4/J4,"n/a")) -> 22.46875 | P4: =IF(L4="HUERFANO","n/a",IFERROR(E4*I4/24000*100,"")) -> 95.2675 | Q4: =IF(L4="HUERFANO","n/a",IFERROR(O4/33*100,"")) -> 68.087121 | R4: =IF(L4="HUERFANO","n/a",IFERROR(MAX(CEILING(P4/100,1),CEILING(Q4/100,1)),"")) -> 1 | S4: =IF(L4="HUERFANO","n/a",IFERROR(MAX(P4,Q4)/(R4*100)*100,"")) -> 95.2675 | T4: =IF(L4="HUERFANO","n/a",IF(S4<75,"CARGA INEFICIENTE","OK")) -> OK | U4: =IF(L4="HUERFANO","n/a",IF(AND(LEFT(D4,3)="LAC",(K4-M4)/K4*100<70),"FEFO RIESGO","OK")) -> OK | V4: =IF(L4="HUERFANO","n/a",IF(AND(G4="In Transit",M4>5),"FANTASMA","OK")) -> OK
A5: SO-50098 | B5: PL-CEN | C5: CD-VER | D5: ABA-1008 | E5: 2130 | F5: 46174 | G5: In Transit | H5: OK | I5: 10.6 | J5: 96 | K5: 445 | L5: OK | M5: 3 | O5: =IF(L5="HUERFANO","n/a",IF(ISNUMBER(J5),E5/J5,"n/a")) -> 22.1875 | P5: =IF(L5="HUERFANO","n/a",IFERROR(E5*I5/24000*100,"")) -> 94.075 | Q5: =IF(L5="HUERFANO","n/a",IFERROR(O5/33*100,"")) -> 67.234848 | R5: =IF(L5="HUERFANO","n/a",IFERROR(MAX(CEILING(P5/100,1),CEILING(Q5/100,1)),"")) -> 1 | S5: =IF(L5="HUERFANO","n/a",IFERROR(MAX(P5,Q5)/(R5*100)*100,"")) -> 94.075 | T5: =IF(L5="HUERFANO","n/a",IF(S5<75,"CARGA INEFICIENTE","OK")) -> OK | U5: =IF(L5="HUERFANO","n/a",IF(AND(LEFT(D5,3)="LAC",(K5-M5)/K5*100<70),"FEFO RIESGO","OK")) -> OK | V5: =IF(L5="HUERFANO","n/a",IF(AND(G5="In Transit",M5>5),"FANTASMA","OK")) -> OK
A6: SO-50626 | B6: PL-SUR | C6: CD-LEO | D6: BOT-1001 | E6: 1998 | F6: 46175 | G6: Delivered | H6: OK | I6: 6.95 | J6: 66 | K6: 95 | L6: OK | M6: 2 | O6: =IF(L6="HUERFANO","n/a",IF(ISNUMBER(J6),E6/J6,"n/a")) -> 30.272727 | P6: =IF(L6="HUERFANO","n/a",IFERROR(E6*I6/24000*100,"")) -> 57.85875 | Q6: =IF(L6="HUERFANO","n/a",IFERROR(O6/33*100,"")) -> 91.735537 | R6: =IF(L6="HUERFANO","n/a",IFERROR(MAX(CEILING(P6/100,1),CEILING(Q6/100,1)),"")) -> 1 | S6: =IF(L6="HUERFANO","n/a",IFERROR(MAX(P6,Q6)/(R6*100)*100,"")) -> 91.735537 | T6: =IF(L6="HUERFANO","n/a",IF(S6<75,"CARGA INEFICIENTE","OK")) -> OK | U6: =IF(L6="HUERFANO","n/a",IF(AND(LEFT(D6,3)="LAC",(K6-M6)/K6*100<70),"FEFO RIESGO","OK")) -> OK | V6: =IF(L6="HUERFANO","n/a",IF(AND(G6="In Transit",M6>5),"FANTASMA","OK")) -> OK
A7: SO-51098 | B7: PL-CEN | C7: CD-TOL | D7: BOT-1001 | E7: 2091 | F7: 46170 | G7: In Transit | H7: OK | I7: 6.95 | J7: 66 | K7: 95 | L7: OK | M7: 7 | O7: =IF(L7="HUERFANO","n/a",IF(ISNUMBER(J7),E7/J7,"n/a")) -> 31.681818 | P7: =IF(L7="HUERFANO","n/a",IFERROR(E7*I7/24000*100,"")) -> 60.551875 | Q7: =IF(L7="HUERFANO","n/a",IFERROR(O7/33*100,"")) -> 96.00551 | R7: =IF(L7="HUERFANO","n/a",IFERROR(MAX(CEILING(P7/100,1),CEILING(Q7/100,1)),"")) -> 1 | S7: =IF(L7="HUERFANO","n/a",IFERROR(MAX(P7,Q7)/(R7*100)*100,"")) -> 96.00551 | T7: =IF(L7="HUERFANO","n/a",IF(S7<75,"CARGA INEFICIENTE","OK")) -> OK | U7: =IF(L7="HUERFANO","n/a",IF(AND(LEFT(D7,3)="LAC",(K7-M7)/K7*100<70),"FEFO RIESGO","OK")) -> OK | V7: =IF(L7="HUERFANO","n/a",IF(AND(G7="In Transit",M7>5),"FANTASMA","OK")) -> FANTASMA
A8: SO-51025 | B8: PL-SUR | C8: CD-CAN | D8: LAC-1003 | E8: 2320 | F8: 46162 | G8: In Transit | H8: OK | I8: 9.02 | J8: 114 | K8: 18 | L8: OK | M8: 15 | O8: =IF(L8="HUERFANO","n/a",IF(ISNUMBER(J8),E8/J8,"n/a")) -> 20.350877 | P8: =IF(L8="HUERFANO","n/a",IFERROR(E8*I8/24000*100,"")) -> 87.193333 | Q8: =IF(L8="HUERFANO","n/a",IFERROR(O8/33*100,"")) -> 61.669325 | R8: =IF(L8="HUERFANO","n/a",IFERROR(MAX(CEILING(P8/100,1),CEILING(Q8/100,1)),"")) -> 1 | S8: =IF(L8="HUERFANO","n/a",IFERROR(MAX(P8,Q8)/(R8*100)*100,"")) -> 87.193333 | T8: =IF(L8="HUERFANO","n/a",IF(S8<75,"CARGA INEFICIENTE","OK")) -> OK | U8: =IF(L8="HUERFANO","n/a",IF(AND(LEFT(D8,3)="LAC",(K8-M8)/K8*100<70),"FEFO RIESGO","OK")) -> FEFO RIESGO | V8: =IF(L8="HUERFANO","n/a",IF(AND(G8="In Transit",M8>5),"FANTASMA","OK")) -> FANTASMA
A9: SO-50981 | B9: PL-SUR | C9: CD-GDL | D9: LAC-1003 | E9: 2296 | F9: 46176 | G9: In Transit | H9: OK | I9: 9.02 | J9: 114 | K9: 18 | L9: OK | M9: 1 | O9: =IF(L9="HUERFANO","n/a",IF(ISNUMBER(J9),E9/J9,"n/a")) -> 20.140351 | P9: =IF(L9="HUERFANO","n/a",IFERROR(E9*I9/24000*100,"")) -> 86.291333 | Q9: =IF(L9="HUERFANO","n/a",IFERROR(O9/33*100,"")) -> 61.031366 | R9: =IF(L9="HUERFANO","n/a",IFERROR(MAX(CEILING(P9/100,1),CEILING(Q9/100,1)),"")) -> 1 | S9: =IF(L9="HUERFANO","n/a",IFERROR(MAX(P9,Q9)/(R9*100)*100,"")) -> 86.291333 | T9: =IF(L9="HUERFANO","n/a",IF(S9<75,"CARGA INEFICIENTE","OK")) -> OK | U9: =IF(L9="HUERFANO","n/a",IF(AND(LEFT(D9,3)="LAC",(K9-M9)/K9*100<70),"FEFO RIESGO","OK")) -> OK | V9: =IF(L9="HUERFANO","n/a",IF(AND(G9="In Transit",M9>5),"FANTASMA","OK")) -> OK
A10: SO-50240 | B10: PL-CEN | C10: CD-PUE | D10: BOT-1009 | E10: 997 | F10: 46176 | G10: In Transit | H10: OK | I10: 5.25 | J10: 76 | K10: 104 | L10: OK | M10: 1 | O10: =IF(L10="HUERFANO","n/a",IF(ISNUMBER(J10),E10/J10,"n/a")) -> 13.118421 | P10: =IF(L10="HUERFANO","n/a",IFERROR(E10*I10/24000*100,"")) -> 21.809375 | Q10: =IF(L10="HUERFANO","n/a",IFERROR(O10/33*100,"")) -> 39.752791 | R10: =IF(L10="HUERFANO","n/a",IFERROR(MAX(CEILING(P10/100,1),CEILING(Q10/100,1)),"")) -> 1 | S10: =IF(L10="HUERFANO","n/a",IFERROR(MAX(P10,Q10)/(R10*100)*100,"")) -> 39.752791 | T10: =IF(L10="HUERFANO","n/a",IF(S10<75,"CARGA INEFICIENTE","OK")) -> CARGA INEFICIENTE | U10: =IF(L10="HUERFANO","n/a",IF(AND(LEFT(D10,3)="LAC",(K10-M10)/K10*100<70),"FEFO RIESGO","OK")) -> OK | V10: =IF(L10="HUERFANO","n/a",IF(AND(G10="In Transit",M10>5),"FANTASMA","OK")) -> OK
A11: SO-50101 | B11: PL-CEN | C11: CD-TOL | D11: BOT-1011 | E11: 2534 | F11: 46176 | G11: In Transit | H11: OK | I11: 3.43 | J11: 88 | K11: 109 | L11: OK | M11: 1 | O11: =IF(L11="HUERFANO","n/a",IF(ISNUMBER(J11),E11/J11,"n/a")) -> 28.795455 | P11: =IF(L11="HUERFANO","n/a",IFERROR(E11*I11/24000*100,"")) -> 36.215083 | Q11: =IF(L11="HUERFANO","n/a",IFERROR(O11/33*100,"")) -> 87.258953 | R11: =IF(L11="HUERFANO","n/a",IFERROR(MAX(CEILING(P11/100,1),CEILING(Q11/100,1)),"")) -> 1 | S11: =IF(L11="HUERFANO","n/a",IFERROR(MAX(P11,Q11)/(R11*100)*100,"")) -> 87.258953 | T11: =IF(L11="HUERFANO","n/a",IF(S11<75,"CARGA INEFICIENTE","OK")) -> OK | U11: =IF(L11="HUERFANO","n/a",IF(AND(LEFT(D11,3)="LAC",(K11-M11)/K11*100<70),"FEFO RIESGO","OK")) -> OK | V11: =IF(L11="HUERFANO","n/a",IF(AND(G11="In Transit",M11>5),"FANTASMA","OK")) -> OK
A12: SO-50596 | B12: PL-CEN | C12: CD-QRO | D12: BOT-1011 | E12: 2712 | F12: 46175 | G12: In Transit | H12: OK | I12: 3.43 | J12: 88 | K12: 109 | L12: OK | M12: 2 | O12: =IF(L12="HUERFANO","n/a",IF(ISNUMBER(J12),E12/J12,"n/a")) -> 30.818182 | P12: =IF(L12="HUERFANO","n/a",IFERROR(E12*I12/24000*100,"")) -> 38.759 | Q12: =IF(L12="HUERFANO","n/a",IFERROR(O12/33*100,"")) -> 93.38843 | R12: =IF(L12="HUERFANO","n/a",IFERROR(MAX(CEILING(P12/100,1),CEILING(Q12/100,1)),"")) -> 1 | S12: =IF(L12="HUERFANO","n/a",IFERROR(MAX(P12,Q12)/(R12*100)*100,"")) -> 93.38843 | T12: =IF(L12="HUERFANO","n/a",IF(S12<75,"CARGA INEFICIENTE","OK")) -> OK | U12: =IF(L12="HUERFANO","n/a",IF(AND(LEFT(D12,3)="LAC",(K12-M12)/K12*100<70),"FEFO RIESGO","OK")) -> OK | V12: =IF(L12="HUERFANO","n/a",IF(AND(G12="In Transit",M12>5),"FANTASMA","OK")) -> OK
A13: SO-50083 | B13: PL-CEN | C13: CD-VER | D13: BEB-1005 | E13: 901 | F13: 46176 | G13: In Transit | H13: OK | I13: 14.2 | J13: 95 | K13: 277 | L13: OK | M13: 1 | O13: =IF(L13="HUERFANO","n/a",IF(ISNUMBER(J13),E13/J13,"n/a")) -> 9.4842105 | P13: =IF(L13="HUERFANO","n/a",IFERROR(E13*I13/24000*100,"")) -> 53.309167 | Q13: =IF(L13="HUERFANO","n/a",IFERROR(O13/33*100,"")) -> 28.740032 | R13: =IF(L13="HUERFANO","n/a",IFERROR(MAX(CEILING(P13/100,1),CEILING(Q13/100,1)),"")) -> 1 | S13: =IF(L13="HUERFANO","n/a",IFERROR(MAX(P13,Q13)/(R13*100)*100,"")) -> 53.309167 | T13: =IF(L13="HUERFANO","n/a",IF(S13<75,"CARGA INEFICIENTE","OK")) -> CARGA INEFICIENTE | U13: =IF(L13="HUERFANO","n/a",IF(AND(LEFT(D13,3)="LAC",(K13-M13)/K13*100<70),"FEFO RIESGO","OK")) -> OK | V13: =IF(L13="HUERFANO","n/a",IF(AND(G13="In Transit",M13>5),"FANTASMA","OK")) -> OK
... A1106: SO-50886 | B1106: PL-NTE | C1106: CD-SAL | D1106: BEB-1000 | E1106: 1170 | F1106: 46176 | G1106: In Transit | H1106: OK | I1106: 16.49 | J1106: 102 | K1106: 315 | L1106: OK | M1106: 1 | O1106: =IF(L1106="HUERFANO","n/a",IF(ISNUMBER(J1106),E1106/J1106,"n/a")) -> 11.470588 | P1106: =IF(L1106="HUERFANO","n/a",IFERROR(E1106*I1106/24000*100,"")) -> 80.38875 | Q1106: =IF(L1106="HUERFANO","n/a",IFERROR(O1106/33*100,"")) -> 34.759358 | R1106: =IF(L1106="HUERFANO","n/a",IFERROR(MAX(CEILING(P1106/100,1),CEILING(Q1106/100,1)),"")) -> 1 | S1106: =IF(L1106="HUERFANO","n/a",IFERROR(MAX(P1106,Q1106)/(R1106*100)*100,"")) -> 80.38875 | T1106: =IF(L1106="HUERFANO","n/a",IF(S1106<75,"CARGA INEFICIENTE","OK")) -> OK | U1106: =IF(L1106="HUERFANO","n/a",IF(AND(LEFT(D1106,3)="LAC",(K1106-M1106)/K1106*100<70),"FEFO RIESGO","OK")) -> OK | V1106: =IF(L1106="HUERFANO","n/a",IF(AND(G1106="In Transit",M1106>5),"FANTASMA","OK")) -> OK

Sheet Excepciones
A1: Tipo de Excepción | B1: Cantidad
A2: Cargas ineficientes | B2: =COUNTIF(Analisis_Transito!T:T, "CARGA INEFICIENTE") -> 361
A3: FEFO en riesgo | B3: =COUNTIF(Analisis_Transito!U:U, "FEFO RIESGO") -> 45
A4: Envíos fantasma | B4: =COUNTIF(Analisis_Transito!V:V, "FANTASMA") -> 51
A5: Órdenes huérfanas | B5: =COUNTIF(Analisis_Transito!L:L, "HUERFANO") -> 12
A6: Demanda no cubierta (unidades) | B6: =SUMIF(Fair_Share!N:N, "ESCASEZ", Fair_Share!O:O) -> 22717.6

Sheet Fair_Share
A1: {=Inventory_Clean[#All]} -> DC | B1: Item_Code | C1: Current_Inventory | D1: Avg_Daily_Demand | E1: Demand_StdDev | F1: Lead_Time_Days | G1: Lead_Time_StdDev | H1: Inv_Quality | J1: Demanda_Total_SKU | K1: Suministro_SKU | L1: Ratio_Cobertura | M1: Asignacion_Fair_Share | N1: Estatus_Suministro | O1: Demanda_No_Cubierta
A2: CD-TOL | B2: PRO-1014 | C2: 2862 | D2: 395 | E2: 268.5 | F2: 2 | G2: 0.5 | H2: OK | J2: =SUMIF($B$2:$B$1501, B2, $D$2:$D$1501) -> 5634.1 | K2: =SUMIF(Supply_Clean[Item_Code], B2, Supply_Clean[Available_Supply]) -> 16301 | L2: =IFERROR(MIN(1, K2/J2), "") -> 1 | M2: =IFERROR(D2*L2, "") -> 395 | N2: =IF(L2<1, "ESCASEZ", "SUFICIENTE") -> SUFICIENTE | O2: =IF(N2="ESCASEZ", D2-M2, 0) -> 0
A3: CD-CDMX | B3: BOT-1006 | C3: 3657 | D3: 408.6 | E3: 117.3 | F3: 0.7 | G3: 0.2 | H3: OK | J3: =SUMIF($B$2:$B$1501, B3, $D$2:$D$1501) -> 7732.6 | K3: =SUMIF(Supply_Clean[Item_Code], B3, Supply_Clean[Available_Supply]) -> 16401 | L3: =IFERROR(MIN(1, K3/J3), "") -> 1 | M3: =IFERROR(D3*L3, "") -> 408.6 | N3: =IF(L3<1, "ESCASEZ", "SUFICIENTE") -> SUFICIENTE | O3: =IF(N3="ESCASEZ", D3-M3, 0) -> 0
A4: CD-VER | B4: BEB-1011 | C4: 4182 | D4: 0 | E4: 63.7 | F4: 5 | G4: 0.9 | H4: OK | J4: =SUMIF($B$2:$B$1501, B4, $D$2:$D$1501) -> 5454.5 | K4: =SUMIF(Supply_Clean[Item_Code], B4, Supply_Clean[Available_Supply]) -> 13720 | L4: =IFERROR(MIN(1, K4/J4), "") -> 1 | M4: =IFERROR(D4*L4, "") -> 0 | N4: =IF(L4<1, "ESCASEZ", "SUFICIENTE") -> SUFICIENTE | O4: =IF(N4="ESCASEZ", D4-M4, 0) -> 0
A5: CD-TOL | B5: ABA-1007 | C5: 8913 | D5: 553.8 | E5: 67.5 | F5: 1.7 | G5: 0.5 | H5: OK | J5: =SUMIF($B$2:$B$1501, B5, $D$2:$D$1501) -> 4867.3 | K5: =SUMIF(Supply_Clean[Item_Code], B5, Supply_Clean[Available_Supply]) -> 13182 | L5: =IFERROR(MIN(1, K5/J5), "") -> 1 | M5: =IFERROR(D5*L5, "") -> 553.8 | N5: =IF(L5<1, "ESCASEZ", "SUFICIENTE") -> SUFICIENTE | O5: =IF(N5="ESCASEZ", D5-M5, 0) -> 0
A6: CD-CDMX | B6: BEB-1000 | C6: 6474 | D6: 366.7 | E6: 43.8 | F6: 0.7 | G6: 0.2 | H6: OK | J6: =SUMIF($B$2:$B$1501, B6, $D$2:$D$1501) -> 4843.5 | K6: =SUMIF(Supply_Clean[Item_Code], B6, Supply_Clean[Available_Supply]) -> 14592 | L6: =IFERROR(MIN(1, K6/J6), "") -> 1 | M6: =IFERROR(D6*L6, "") -> 366.7 | N6: =IF(L6<1, "ESCASEZ", "SUFICIENTE") -> SUFICIENTE | O6: =IF(N6="ESCASEZ", D6-M6, 0) -> 0
A7: CD-CDMX | B7: BOT-1013 | C7: 7599 | D7: 454.2 | E7: 93.4 | F7: 1.1 | G7: 0.2 | H7: OK | J7: =SUMIF($B$2:$B$1501, B7, $D$2:$D$1501) -> 8336.2 | K7: =SUMIF(Supply_Clean[Item_Code], B7, Supply_Clean[Available_Supply]) -> 20545 | L7: =IFERROR(MIN(1, K7/J7), "") -> 1 | M7: =IFERROR(D7*L7, "") -> 454.2 | N7: =IF(L7<1, "ESCASEZ", "SUFICIENTE") -> SUFICIENTE | O7: =IF(N7="ESCASEZ", D7-M7, 0) -> 0
A8: CD-VER | B8: BOT-1010 | C8: 6848 | D8: 784.3 | E8: 122.2 | F8: 3.1 | G8: 0.9 | H8: OK | J8: =SUMIF($B$2:$B$1501, B8, $D$2:$D$1501) -> 7108.7 | K8: =SUMIF(Supply_Clean[Item_Code], B8, Supply_Clean[Available_Supply]) -> 21582 | L8: =IFERROR(MIN(1, K8/J8), "") -> 1 | M8: =IFERROR(D8*L8, "") -> 784.3 | N8: =IF(L8<1, "ESCASEZ", "SUFICIENTE") -> SUFICIENTE | O8: =IF(N8="ESCASEZ", D8-M8, 0) -> 0
A9: CD-CHI | B9: LAC-1006 | C9: 1444 | D9: 209.7 | E9: 56.1 | F9: 3.1 | G9: 1 | H9: OK | J9: =SUMIF($B$2:$B$1501, B9, $D$2:$D$1501) -> 4338.7 | K9: =SUMIF(Supply_Clean[Item_Code], B9, Supply_Clean[Available_Supply]) -> 10670 | L9: =IFERROR(MIN(1, K9/J9), "") -> 1 | M9: =IFERROR(D9*L9, "") -> 209.7 | N9: =IF(L9<1, "ESCASEZ", "SUFICIENTE") -> SUFICIENTE | O9: =IF(N9="ESCASEZ", D9-M9, 0) -> 0
A10: CD-VER | B10: BOT-1012 | C10: 16574 | D10: 948.9 | E10: 207.4 | F10: 0.9 | G10: 0.9 | H10: OK | J10: =SUMIF($B$2:$B$1501, B10, $D$2:$D$1501) -> 9259.4 | K10: =SUMIF(Supply_Clean[Item_Code], B10, Supply_Clean[Available_Supply]) -> 13943 | L10: =IFERROR(MIN(1, K10/J10), "") -> 1 | M10: =IFERROR(D10*L10, "") -> 948.9 | N10: =IF(L10<1, "ESCASEZ", "SUFICIENTE") -> SUFICIENTE | O10: =IF(N10="ESCASEZ", D10-M10, 0) -> 0
A11: CD-PUE | B11: ABA-1007 | C11: 1422 | D11: 289.9 | E11: 31.2 | F11: 0.5 | G11: 0.3 | H11: OK | J11: =SUMIF($B$2:$B$1501, B11, $D$2:$D$1501) -> 4867.3 | K11: =SUMIF(Supply_Clean[Item_Code], B11, Supply_Clean[Available_Supply]) -> 13182 | L11: =IFERROR(MIN(1, K11/J11), "") -> 1 | M11: =IFERROR(D11*L11, "") -> 289.9 | N11: =IF(L11<1, "ESCASEZ", "SUFICIENTE") -> SUFICIENTE | O11: =IF(N11="ESCASEZ", D11-M11, 0) -> 0
A12: CD-CHI | B12: PRO-1001 | C12: 8663 | D12: 495.2 | E12: 204.3 | F12: 2.1 | G12: 1 | H12: OK | J12: =SUMIF($B$2:$B$1501, B12, $D$2:$D$1501) -> 6433.3 | K12: =SUMIF(Supply_Clean[Item_Code], B12, Supply_Clean[Available_Supply]) -> 10011 | L12: =IFERROR(MIN(1, K12/J12), "") -> 1 | M12: =IFERROR(D12*L12, "") -> 495.2 | N12: =IF(L12<1, "ESCASEZ", "SUFICIENTE") -> SUFICIENTE | O12: =IF(N12="ESCASEZ", D12-M12, 0) -> 0
A13: CD-TIJ | B13: BOT-1016 | C13: 580 | D13: 800.5 | E13: 236.1 | F13: 3.4 | G13: 1.5 | H13: OK | J13: =SUMIF($B$2:$B$1501, B13, $D$2:$D$1501) -> 9923.7 | K13: =SUMIF(Supply_Clean[Item_Code], B13, Supply_Clean[Available_Supply]) -> 18995 | L13: =IFERROR(MIN(1, K13/J13), "") -> 1 | M13: =IFERROR(D13*L13, "") -> 800.5 | N13: =IF(L13<1, "ESCASEZ", "SUFICIENTE") -> SUFICIENTE | O13: =IF(N13="ESCASEZ", D13-M13, 0) -> 0
... A37: CD-QRO | B37: ABA-1004 | C37: 1575 | D37: 188.3 | E37: 17.7 | F37: 1.8 | G37: 0.4 | H37: OK | J37: =SUMIF($B$2:$B$1501, B37, $D$2:$D$1501) -> 5236.7 | K37: =SUMIF(Supply_Clean[Item_Code], B37, Supply_Clean[Available_Supply]) -> 10879 | L37: =IFERROR(MIN(1, K37/J37), "") -> 1 | M37: =IFERROR(D37*L37, "") -> 188.3 | N37: =IF(L37<1, "ESCASEZ", "SUFICIENTE") -> SUFICIENTE | O37: =IF(N37="ESCASEZ", D37-M37, 0) -> 0
A38: CD-SAL | B38: LAC-1000 | C38: 0 | D38: 334.9 | E38: 99.2 | F38: 1.7 | G38: 0.5 | H38: 0 | J38: =SUMIF($B$2:$B$1501, B38, $D$2:$D$1501) -> 4987.8 | K38: =SUMIF(Supply_Clean[Item_Code], B38, Supply_Clean[Available_Supply]) -> 12568 | L38: =IFERROR(MIN(1, K38/J38), "") -> 1 | M38: =IFERROR(D38*L38, "") -> 334.9 | N38: =IF(L38<1, "ESCASEZ", "SUFICIENTE") -> SUFICIENTE | O38: =IF(N38="ESCASEZ", D38-M38, 0) -> 0
A39: CD-MTY | B39: BOT-1003 | C39: 9638 | D39: 541.9 | E39: 88.2 | F39: 1.1 | G39: 0.3 | H39: OK | J39: =SUMIF($B$2:$B$1501, B39, $D$2:$D$1501) -> 8902.8 | K39: =SUMIF(Supply_Clean[Item_Code], B39, Supply_Clean[Available_Supply]) -> 24326 | L39: =IFERROR(MIN(1, K39/J39), "") -> 1 | M39: =IFERROR(D39*L39, "") -> 541.9 | N39: =IF(L39<1, "ESCASEZ", "SUFICIENTE") -> SUFICIENTE | O39: =IF(N39="ESCASEZ", D39-M39, 0) -> 0
A40: CD-CHI | B40: LAC-1010 | C40: 4103 | D40: 485.8 | E40: 198.2 | F40: 2.5 | G40: 1 | H40: OK | J40: =SUMIF($B$2:$B$1501, B40, $D$2:$D$1501) -> 4321.7 | K40: =SUMIF(Supply_Clean[Item_Code], B40, Supply_Clean[Available_Supply]) -> 11567 | L40: =IFERROR(MIN(1, K40/J40), "") -> 1 | M40: =IFERROR(D40*L40, "") -> 485.8 | N40: =IF(L40<1, "ESCASEZ", "SUFICIENTE") -> SUFICIENTE | O40: =IF(N40="ESCASEZ", D40-M40, 0) -> 0
A41: CD-MOR | B41: BEB-1002 | C41: 2497 | D41: 162.4 | E41: 19.3 | F41: 1.7 | G41: 0.5 | H41: OK | J41: =SUMIF($B$2:$B$1501, B41, $D$2:$D$1501) -> 6246.8 | K41: =SUMIF(Supply_Clean[Item_Code], B41, Supply_Clean[Available_Supply]) -> 13052 | L41: =IFERROR(MIN(1, K41/J41), "") -> 1 | M41: =IFERROR(D41*L41, "") -> 162.4 | N41: =IF(L41<1, "ESCASEZ", "SUFICIENTE") -> SUFICIENTE | O41: =IF(N41="ESCASEZ", D41-M41, 0) -> 0
A42: CD-CDMX | B42: LAC-1008 | C42: 2440 | D42: 275.4 | E42: 102.8 | F42: 0.6 | G42: 0.2 | H42: OK | J42: =SUMIF($B$2:$B$1501, B42, $D$2:$D$1501) -> 4499.1 | K42: =SUMIF(Supply_Clean[Item_Code], B42, Supply_Clean[Available_Supply]) -> 9543 | L42: =IFERROR(MIN(1, K42/J42), "") -> 1 | M42: =IFERROR(D42*L42, "") -> 275.4 | N42: =IF(L42<1, "ESCASEZ", "SUFICIENTE") -> SUFICIENTE | O42: =IF(N42="ESCASEZ", D42-M42, 0) -> 0
A43: CD-QRO | B43: BOT-1014 | C43: 1048 | D43: 360.1 | E43: 85.6 | F43: 1.7 | G43: 0.4 | H43: OK | J43: =SUMIF($B$2:$B$1501, B43, $D$2:$D$1501) -> 8056.4 | K43: =SUMIF(Supply_Clean[Item_Code], B43, Supply_Clean[Available_Supply]) -> 14373 | L43: =IFERROR(MIN(1, K43/J43), "") -> 1 | M43: =IFERROR(D43*L43, "") -> 360.1 | N43: =IF(L43<1, "ESCASEZ", "SUFICIENTE") -> SUFICIENTE | O43: =IF(N43="ESCASEZ", D43-M43, 0) -> 0
A44: CD-GDL | B44: PRO-1000 | C44: 3885 | D44: 394.7 | E44: 258.3 | F44: 0.5 | G44: 0.2 | H44: OK | J44: =SUMIF($B$2:$B$1501, B44, $D$2:$D$1501) -> 5872.7 | K44: =SUMIF(Supply_Clean[Item_Code], B44, Supply_Clean[Available_Supply]) -> 2915 | L44: =IFERROR(MIN(1, K44/J44), "") -> 0.49636453 | M44: =IFERROR(D44*L44, "") -> 195.91508 | N44: =IF(L44<1, "ESCASEZ", "SUFICIENTE") -> ESCASEZ | O44: =IF(N44="ESCASEZ", D44-M44, 0) -> 198.78492
A45: CD-QRO | B45: LAC-1008 | C45: 2600 | D45: 152.7 | E45: 51.4 | F45: 1.7 | G45: 0.4 | H45: OK | J45: =SUMIF($B$2:$B$1501, B45, $D$2:$D$1501) -> 4499.1 | K45: =SUMIF(Supply_Clean[Item_Code], B45, Supply_Clean[Available_Supply]) -> 9543 | L45: =IFERROR(MIN(1, K45/J45), "") -> 1 | M45: =IFERROR(D45*L45, "") -> 152.7 | N45: =IF(L45<1, "ESCASEZ", "SUFICIENTE") -> SUFICIENTE | O45: =IF(N45="ESCASEZ", D45-M45, 0) -> 0
A46: CD-CHI | B46: BOT-1010 | C46: 5685 | D46: 352.1 | E46: 103.1 | F46: 4.2 | G46: 1 | H46: OK | J46: =SUMIF($B$2:$B$1501, B46, $D$2:$D$1501) -> 7108.7 | K46: =SUMIF(Supply_Clean[Item_Code], B46, Supply_Clean[Available_Supply]) -> 21582 | L46: =IFERROR(MIN(1, K46/J46), "") -> 1 | M46: =IFERROR(D46*L46, "") -> 352.1 | N46: =IF(L46<1, "ESCASEZ", "SUFICIENTE") -> SUFICIENTE | O46: =IF(N46="ESCASEZ", D46-M46, 0) -> 0
A47: CD-MER | B47: BOT-1016 | C47: 2068 | D47: 378.2 | E47: 89.2 | F47: 1.8 | G47: 1.3 | H47: OK | J47: =SUMIF($B$2:$B$1501, B47, $D$2:$D$1501) -> 9923.7 | K47: =SUMIF(Supply_Clean[Item_Code], B47, Supply_Clean[Available_Supply]) -> 18995 | L47: =IFERROR(MIN(1, K47/J47), "") -> 1 | M47: =IFERROR(D47*L47, "") -> 378.2 | N47: =IF(L47<1, "ESCASEZ", "SUFICIENTE") -> SUFICIENTE | O47: =IF(N47="ESCASEZ", D47-M47, 0) -> 0
A48: CD-SAL | B48: BOT-1009 | C48: 10536 | D48: 627 | E48: 160.4 | F48: 2 | G48: 0.5 | H48: OK | J48: =SUMIF($B$2:$B$1501, B48, $D$2:$D$1501) -> 8135.5 | K48: =SUMIF(Supply_Clean[Item_Code], B48, Supply_Clean[Available_Supply]) -> 17475 | L48: =IFERROR(MIN(1, K48/J48), "") -> 1 | M48: =IFERROR(D48*L48, "") -> 627 | N48: =IF(L48<1, "ESCASEZ", "SUFICIENTE") -> SUFICIENTE | O48: =IF(N48="ESCASEZ", D48-M48, 0) -> 0
A49: CD-CAN | B49: ABA-1006 | C49: 6643 | D49: 463.7 | E49: 43.5 | F49: 7.7 | G49: 1.6 | H49: OK | J49: =SUMIF($B$2:$B$1501, B49, $D$2:$D$1501) -> 4882.1 | K49: =SUMIF(Supply_Clean[Item_Code], B49, Supply_Clean[Available_Supply]) -> 15586 | L49: =IFERROR(MIN(1, K49/J49), "") -> 1 | M49: =IFERROR(D49*L49, "") -> 463.7 | N49: =IF(L49<1, "ESCASEZ", "SUFICIENTE") -> SUFICIENTE | O49: =IF(N49="ESCASEZ", D49-M49, 0) -> 0
A50: CD-MTY | B50: LAC-1000 | C50: 3134 | D50: 370.7 | E50: 133.6 | F50: 1.3 | G50: 0.3 | H50: OK | J50: =SUMIF($B$2:$B$1501, B50, $D$2:$D$1501) -> 4987.8 | K50: =SUMIF(Supply_Clean[Item_Code], B50, Supply_Clean[Available_Supply]) -> 12568 | L50: =IFERROR(MIN(1, K50/J50), "") -> 1 | M50: =IFERROR(D50*L50, "") -> 370.7 | N50: =IF(L50<1, "ESCASEZ", "SUFICIENTE") -> SUFICIENTE | O50: =IF(N50="ESCASEZ", D50-M50, 0) -> 0
... A56: CD-QRO | B56: LAC-1010 | C56: 5387 | D56: 315.9 | E56: 131.3 | F56: 1.7 | G56: 0.4 | H56: OK | J56: =SUMIF($B$2:$B$1501, B56, $D$2:$D$1501) -> 4321.7 | K56: =SUMIF(Supply_Clean[Item_Code], B56, Supply_Clean[Available_Supply]) -> 11567 | L56: =IFERROR(MIN(1, K56/J56), "") -> 1 | M56: =IFERROR(D56*L56, "") -> 315.9 | N56: =IF(L56<1, "ESCASEZ", "SUFICIENTE") -> SUFICIENTE | O56: =IF(N56="ESCASEZ", D56-M56, 0) -> 0
A57: CD-GDL | B57: BEB-1021 | C57: 0 | D57: 414.7 | E57: 49.3 | F57: 1.1 | G57: 0.2 | H57: 0 | J57: =SUMIF($B$2:$B$1501, B57, $D$2:$D$1501) -> 5254.8 | K57: =SUMIF(Supply_Clean[Item_Code], B57, Supply_Clean[Available_Supply]) -> 13235 | L57: =IFERROR(MIN(1, K57/J57), "") -> 1 | M57: =IFERROR(D57*L57, "") -> 414.7 | N57: =IF(L57<1, "ESCASEZ", "SUFICIENTE") -> SUFICIENTE | O57: =IF(N57="ESCASEZ", D57-M57, 0) -> 0
A58: CD-MER | B58: BEB-1020 | C58: 3654 | D58: 468.4 | E58: 83.8 | F58: 1.5 | G58: 1.3 | H58: OK | J58: =SUMIF($B$2:$B$1501, B58, $D$2:$D$1501) -> 6114.4 | K58: =SUMIF(Supply_Clean[Item_Code], B58, Supply_Clean[Available_Supply]) -> 16621 | L58: =IFERROR(MIN(1, K58/J58), "") -> 1 | M58: =IFERROR(D58*L58, "") -> 468.4 | N58: =IF(L58<1, "ESCASEZ", "SUFICIENTE") -> SUFICIENTE | O58: =IF(N58="ESCASEZ", D58-M58, 0) -> 0
A59: CD-MER | B59: PRO-1000 | C59: 2172 | D59: 170.9 | E59: 106.9 | F59: 5.1 | G59: 1.3 | H59: OK | J59: =SUMIF($B$2:$B$1501, B59, $D$2:$D$1501) -> 5872.7 | K59: =SUMIF(Supply_Clean[Item_Code], B59, Supply_Clean[Available_Supply]) -> 2915 | L59: =IFERROR(MIN(1, K59/J59), "") -> 0.49636453 | M59: =IFERROR(D59*L59, "") -> 84.828699 | N59: =IF(L59<1, "ESCASEZ", "SUFICIENTE") -> ESCASEZ | O59: =IF(N59="ESCASEZ", D59-M59, 0) -> 86.071301
A60: CD-HER | B60: BEB-1009 | C60: 2699 | D60: 196 | E60: 31.3 | F60: 2.9 | G60: 1.2 | H60: OK | J60: =SUMIF($B$2:$B$1501, B60, $D$2:$D$1501) -> 6226.9 | K60: =SUMIF(Supply_Clean[Item_Code], B60, Supply_Clean[Available_Supply]) -> 10475 | L60: =IFERROR(MIN(1, K60/J60), "") -> 1 | M60: =IFERROR(D60*L60, "") -> 196 | N60: =IF(L60<1, "ESCASEZ", "SUFICIENTE") -> SUFICIENTE | O60: =IF(N60="ESCASEZ", D60-M60, 0) -> 0
A61: CD-CDMX | B61: ABA-1001 | C61: 1154 | D61: 362.4 | E61: 45.4 | F61: 1.2 | G61: 0.2 | H61: OK | J61: =SUMIF($B$2:$B$1501, B61, $D$2:$D$1501) -> 4698.7 | K61: =SUMIF(Supply_Clean[Item_Code], B61, Supply_Clean[Available_Supply]) -> 8775 | L61: =IFERROR(MIN(1, K61/J61), "") -> 1 | M61: =IFERROR(D61*L61, "") -> 362.4 | N61: =IF(L61<1, "ESCASEZ", "SUFICIENTE") -> SUFICIENTE | O61: =IF(N61="ESCASEZ", D61-M61, 0) -> 0
A62: CD-QRO | B62: BEB-1017 | C62: 0 | D62: 349.7 | E62: 68.7 | F62: 1.1 | G62: 0.4 | H62: 0 | J62: =SUMIF($B$2:$B$1501, B62, $D$2:$D$1501) -> 6231.7 | K62: =SUMIF(Supply_Clean[Item_Code], B62, Supply_Clean[Available_Supply]) -> 18257 | L62: =IFERROR(MIN(1, K62/J62), "") -> 1 | M62: =IFERROR(D62*L62, "") -> 349.7 | N62: =IF(L62<1, "ESCASEZ", "SUFICIENTE") -> SUFICIENTE | O62: =IF(N62="ESCASEZ", D62-M62, 0) -> 0
A63: CD-TIJ | B63: ABA-1007 | C63: 0 | D63: 336.6 | E63: 38.2 | F63: 5.9 | G63: 1.5 | H63: 0 | J63: =SUMIF($B$2:$B$1501, B63, $D$2:$D$1501) -> 4867.3 | K63: =SUMIF(Supply_Clean[Item_Code], B63, Supply_Clean[Available_Supply]) -> 13182 | L63: =IFERROR(MIN(1, K63/J63), "") -> 1 | M63: =IFERROR(D63*L63, "") -> 336.6 | N63: =IF(L63<1, "ESCASEZ", "SUFICIENTE") -> SUFICIENTE | O63: =IF(N63="ESCASEZ", D63-M63, 0) -> 0
A64: CD-MER | B64: LAC-1001 | C64: 2390 | D64: 265.8 | E64: 95 | F64: 6.3 | G64: 1.3 | H64: OK | J64: =SUMIF($B$2:$B$1501, B64, $D$2:$D$1501) -> 3661 | K64: =SUMIF(Supply_Clean[Item_Code], B64, Supply_Clean[Available_Supply]) -> 9945 | L64: =IFERROR(MIN(1, K64/J64), "") -> 1 | M64: =IFERROR(D64*L64, "") -> 265.8 | N64: =IF(L64<1, "ESCASEZ", "SUFICIENTE") -> SUFICIENTE | O64: =IF(N64="ESCASEZ", D64-M64, 0) -> 0
A65: CD-CAN | B65: LAC-1010 | C65: 1363 | D65: 363.8 | E65: 116.7 | F65: 2.9 | G65: 1.6 | H65: OK | J65: =SUMIF($B$2:$B$1501, B65, $D$2:$D$1501) -> 4321.7 | K65: =SUMIF(Supply_Clean[Item_Code], B65, Supply_Clean[Available_Supply]) -> 11567 | L65: =IFERROR(MIN(1, K65/J65), "") -> 1 | M65: =IFERROR(D65*L65, "") -> 363.8 | N65: =IF(L65<1, "ESCASEZ", "SUFICIENTE") -> SUFICIENTE | O65: =IF(N65="ESCASEZ", D65-M65, 0) -> 0
A66: CD-LEO | B66: BEB-1009 | C66: 3354 | D66: 379.3 | E66: 69.3 | F66: 1.8 | G66: 0.6 | H66: OK | J66: =SUMIF($B$2:$B$1501, B66, $D$2:$D$1501) -> 6226.9 | K66: =SUMIF(Supply_Clean[Item_Code], B66, Supply_Clean[Available_Supply]) -> 10475 | L66: =IFERROR(MIN(1, K66/J66), "") -> 1 | M66: =IFERROR(D66*L66, "") -> 379.3 | N66: =IF(L66<1, "ESCASEZ", "SUFICIENTE") -> SUFICIENTE | O66: =IF(N66="ESCASEZ", D66-M66, 0) -> 0
A67: CD-HER | B67: BEB-1015 | C67: 448 | D67: 324.3 | E67: 47.3 | F67: 3.8 | G67: 1.2 | H67: OK | J67: =SUMIF($B$2:$B$1501, B67, $D$2:$D$1501) -> 5073.1 | K67: =SUMIF(Supply_Clean[Item_Code], B67, Supply_Clean[Available_Supply]) -> 14801 | L67: =IFERROR(MIN(1, K67/J67), "") -> 1 | M67: =IFERROR(D67*L67, "") -> 324.3 | N67: =IF(L67<1, "ESCASEZ", "SUFICIENTE") -> SUFICIENTE | O67: =IF(N67="ESCASEZ", D67-M67, 0) -> 0
A68: CD-TOL | B68: PRO-1007 | C68: 1903 | D68: 0 | E68: 319.6 | F68: 2 | G68: 0.5 | H68: OK | J68: =SUMIF($B$2:$B$1501, B68, $D$2:$D$1501) -> 5354.8 | K68: =SUMIF(Supply_Clean[Item_Code], B68, Supply_Clean[Available_Supply]) -> 10360 | L68: =IFERROR(MIN(1, K68/J68), "") -> 1 | M68: =IFERROR(D68*L68, "") -> 0 | N68: =IF(L68<1, "ESCASEZ", "SUFICIENTE") -> SUFICIENTE | O68: =IF(N68="ESCASEZ", D68-M68, 0) -> 0
...

Sheet Supply_Clean
A1: Plant | B1: Item_Code | C1: Available_Supply
A2: PL-SUR | B2: BEB-1000 | C2: 14592
A3: PL-CEN | B3: BEB-1001 | C3: 11725
A4: PL-NTE | B4: BEB-1002 | C4: 13052
A5: PL-SUR | B5: BEB-1003 | C5: 16426
A6: PL-CEN | B6: BEB-1004 | C6: 15672
A7: PL-CEN | B7: BEB-1005 | C7: 14054
A8: PL-CEN | B8: BEB-1006 | C8: 12324
A9: PL-NTE | B9: BEB-1007 | C9: 12912
A10: PL-SUR | B10: BEB-1008 | C10: 18019
A11: PL-CEN | B11: BEB-1009 | C11: 10475
A12: PL-SUR | B12: BEB-1010 | C12: 3237
A13: PL-CEN | B13: BEB-1011 | C13: 13720
... A101: PL-CEN | B101: PRO-1015 | C101: 15970

Sheet Transit_Clean
A1: Order_ID | B1: Origin | C1: Destination | D1: Item_Code | E1: Quantity | F1: Dispatch_Date | G1: SAP_Status | H1: Qty_Quality
A2: SO-50312 | B2: PL-SUR | C2: CD-MER | D2: LAC-1013 | E2: 2260 | F2: 31/05/2026 | G2: In Transit | H2: OK
A3: SO-50626 | B3: PL-SUR | C3: CD-LEO | D3: BOT-1001 | E3: 1998 | F3: 02/06/2026 | G3: Delivered | H3: OK
A4: SO-51025 | B4: PL-SUR | C4: CD-CAN | D4: LAC-1003 | E4: 2320 | F4: 20/05/2026 | G4: In Transit | H4: OK
A5: SO-50101 | B5: PL-CEN | C5: CD-TOL | D5: BOT-1011 | E5: 2534 | F5: 03/06/2026 | G5: In Transit | H5: OK
A6: SO-50776 | B6: PL-SUR | C6: CD-LEO | D6: PRO-1000 | E6: 1036 | F6: 03/06/2026 | G6: In Transit | H6: OK
A7: SO-50491 | B7: PL-NTE | C7: CD-TIJ | D7: PRO-1005 | E7: 530 | F7: 31/05/2026 | G7: In Transit | H7: OK
A8: SO-50006 | B8: PL-SUR | C8: CD-LEO | D8: PRO-1009 | E8: 1089 | F8: 03/06/2026 | G8: In Transit | H8: OK
A9: SO-50058 | B9: PL-NTE | C9: CD-CHI | D9: LAC-1002 | E9: 2802 | F9: 03/06/2026 | G9: In Transit | H9: OK
A10: SO-51008 | B10: PL-SUR | C10: CD-MOR | D10: LAC-1016 | E10: 1766 | F10: 21/05/2026 | G10: In Transit | H10: OK
A11: SO-50262 | B11: PL-SUR | C11: CD-MOR | D11: LAC-1014 | E11: 2414 | F11: 02/06/2026 | G11: In Transit | H11: OK
A12: SO-50124 | B12: PL-NTE | C12: CD-TIJ | D12: BEB-1006 | E12: 736 | F12: 01/06/2026 | G12: In Transit | H12: OK
A13: SO-50587 | B13: PL-CEN | C13: CD-TOL | D13: ABA-1011 | E13: 2027 | F13: 02/06/2026 | G13: In Transit | H13: OK
... A1106: SO-50886 | B1106: PL-NTE | C1106: CD-SAL | D1106: BEB-1000 | E1106: 1170 | F1106: 03/06/2026 | G1106: In Transit | H1106: OK

Sheet Inventory_Clean
A1: DC | B1: Item_Code | C1: Current_Inventory | D1: Avg_Daily_Demand | E1: Demand_StdDev | F1: Lead_Time_Days | G1: Lead_Time_StdDev | H1: Inv_Quality
A2: CD-TOL | B2: PRO-1014 | C2: 2862 | D2: 395 | E2: 268.5 | F2: 2 | G2: 0.5 | H2: OK
A3: CD-CDMX | B3: BOT-1006 | C3: 3657 | D3: 408.6 | E3: 117.3 | F3: 0.7 | G3: 0.2 | H3: OK
A4: CD-VER | B4: BEB-1011 | C4: 4182 | E4: 63.7 | F4: 5 | G4: 0.9 | H4: OK
A5: CD-TOL | B5: ABA-1007 | C5: 8913 | D5: 553.8 | E5: 67.5 | F5: 1.7 | G5: 0.5 | H5: OK
A6: CD-CDMX | B6: BEB-1000 | C6: 6474 | D6: 366.7 | E6: 43.8 | F6: 0.7 | G6: 0.2 | H6: OK
A7: CD-CDMX | B7: BOT-1013 | C7: 7599 | D7: 454.2 | E7: 93.4 | F7: 1.1 | G7: 0.2 | H7: OK
A8: CD-VER | B8: BOT-1010 | C8: 6848 | D8: 784.3 | E8: 122.2 | F8: 3.1 | G8: 0.9 | H8: OK
A9: CD-CHI | B9: LAC-1006 | C9: 1444 | D9: 209.7 | E9: 56.1 | F9: 3.1 | G9: 1 | H9: OK
A10: CD-VER | B10: BOT-1012 | C10: 16574 | D10: 948.9 | E10: 207.4 | F10: 0.9 | G10: 0.9 | H10: OK
A11: CD-PUE | B11: ABA-1007 | C11: 1422 | D11: 289.9 | E11: 31.2 | F11: 0.5 | G11: 0.3 | H11: OK
A12: CD-CHI | B12: PRO-1001 | C12: 8663 | D12: 495.2 | E12: 204.3 | F12: 2.1 | G12: 1 | H12: OK
A13: CD-TIJ | B13: BOT-1016 | C13: 580 | D13: 800.5 | E13: 236.1 | F13: 3.4 | G13: 1.5 | H13: OK
A14: CD-PUE | B14: BOT-1001 | C14: 4706 | D14: 1097.7 | E14: 258.7 | F14: 0.9 | G14: 0.3 | H14: OK
A15: CD-PUE | B15: BOT-1010 | C15: 1583 | D15: 833.9 | E15: 188.9 | F15: 0.8 | G15: 0.3 | H15: OK
A16: CD-QRO | B16: BEB-1015 | C16: 1077 | D16: 325.9 | E16: 33 | F16: 1.2 | G16: 0.4 | H16: OK
... A37: CD-QRO | B37: ABA-1004 | C37: 1575 | D37: 188.3 | E37: 17.7 | F37: 1.8 | G37: 0.4 | H37: OK
A38: CD-SAL | B38: LAC-1000 | D38: 334.9 | E38: 99.2 | F38: 1.7 | G38: 0.5
A39: CD-MTY | B39: BOT-1003 | C39: 9638 | D39: 541.9 | E39: 88.2 | F39: 1.1 | G39: 0.3 | H39: OK
A40: CD-CHI | B40: LAC-1010 | C40: 4103 | D40: 485.8 | E40: 198.2 | F40: 2.5 | G40: 1 | H40: OK
A41: CD-MOR | B41: BEB-1002 | C41: 2497 | D41: 162.4 | E41: 19.3 | F41: 1.7 | G41: 0.5 | H41: OK
A42: CD-CDMX | B42: LAC-1008 | C42: 2440 | D42: 275.4 | E42: 102.8 | F42: 0.6 | G42: 0.2 | H42: OK
A43: CD-QRO | B43: BOT-1014 | C43: 1048 | D43: 360.1 | E43: 85.6 | F43: 1.7 | G43: 0.4 | H43: OK
A44: CD-GDL | B44: PRO-1000 | C44: 3885 | D44: 394.7 | E44: 258.3 | F44: 0.5 | G44: 0.2 | H44: OK
A45: CD-QRO | B45: LAC-1008 | C45: 2600 | D45: 152.7 | E45: 51.4 | F45: 1.7 | G45: 0.4 | H45: OK
A46: CD-CHI | B46: BOT-1010 | C46: 5685 | D46: 352.1 | E46: 103.1 | F46: 4.2 | G46: 1 | H46: OK
A47: CD-MER | B47: BOT-1016 | C47: 2068 | D47: 378.2 | E47: 89.2 | F47: 1.8 | G47: 1.3 | H47: OK
A48: CD-SAL | B48: BOT-1009 | C48: 10536 | D48: 627 | E48: 160.4 | F48: 2 | G48: 0.5 | H48: OK
A49: CD-CAN | B49: ABA-1006 | C49: 6643 | D49: 463.7 | E49: 43.5 | F49: 7.7 | G49: 1.6 | H49: OK
A50: CD-MTY | B50: LAC-1000 | C50: 3134 | D50: 370.7 | E50: 133.6 | F50: 1.3 | G50: 0.3 | H50: OK
... A56: CD-QRO | B56: LAC-1010 | C56: 5387 | D56: 315.9 | E56: 131.3 | F56: 1.7 | G56: 0.4 | H56: OK
A57: CD-GDL | B57: BEB-1021 | D57: 414.7 | E57: 49.3 | F57: 1.1 | G57: 0.2
A58: CD-MER | B58: BEB-1020 | C58: 3654 | D58: 468.4 | E58: 83.8 | F58: 1.5 | G58: 1.3 | H58: OK
A59: CD-MER | B59: PRO-1000 | C59: 2172 | D59: 170.9 | E59: 106.9 | F59: 5.1 | G59: 1.3 | H59: OK
A60: CD-HER | B60: BEB-1009 | C60: 2699 | D60: 196 | E60: 31.3 | F60: 2.9 | G60: 1.2 | H60: OK
A61: CD-CDMX | B61: ABA-1001 | C61: 1154 | D61: 362.4 | E61: 45.4 | F61: 1.2 | G61: 0.2 | H61: OK
A62: CD-QRO | B62: BEB-1017 | D62: 349.7 | E62: 68.7 | F62: 1.1 | G62: 0.4
A63: CD-TIJ | B63: ABA-1007 | D63: 336.6 | E63: 38.2 | F63: 5.9 | G63: 1.5
A64: CD-MER | B64: LAC-1001 | C64: 2390 | D64: 265.8 | E64: 95 | F64: 6.3 | G64: 1.3 | H64: OK
A65: CD-CAN | B65: LAC-1010 | C65: 1363 | D65: 363.8 | E65: 116.7 | F65: 2.9 | G65: 1.6 | H65: OK
...

Sheet Master_Clean
A1: Item_Code | B1: Description | C1: Category | D1: Weight_kg | E1: Units_Per_Pallet | F1: Shelf_Life_Days
A2: ABA-1008 | B2: Azucar 2Kg | C2: Abarrotes Secos | D2: 10.6 | E2: 96 | F2: 445
A3: ABA-1014 | B3: Harina 2Kg | C3: Abarrotes Secos | D3: 9.56 | E3: 136 | F3: 345
A4: BOT-1009 | B4: Papas Fritas 45G | C4: Botanas Alto Volumen | D4: 5.25 | E4: 76 | F4: 104
A5: BEB-1005 | B5: Refresco Toronja 355Ml | C5: Bebidas Pesadas | D5: 14.2 | E5: 95 | F5: 277
A6: BEB-1002 | B6: Refresco Cola 1L | C6: Bebidas Pesadas | E6: 69 | F6: 291
A7: LAC-1000 | B7: Crema 900Ml | C7: Lacteos Perecederos | D7: 8.18 | E7: 90 | F7: 29
A8: BOT-1016 | B8: Cacahuates 120G | C8: Botanas Alto Volumen | D8: 5.53 | E8: 42 | F8: 114
A9: PRO-1009 | B9: Temporada Pack 6 | C9: Estacional Promo | D9: 11.96 | E9: 101 | F9: 90
A10: BEB-1000 | B10: Te Helado 1L | C10: Bebidas Pesadas | D10: 16.49 | E10: 102 | F10: 315
A11: BOT-1017 | B11: Frituras Maiz 170G | C11: Botanas Alto Volumen | D11: 3.75 | E11: 41 | F11: 106
A12: LAC-1014 | B12: Yogurt Griego 1000G | C12: Lacteos Perecederos | D12: 8.05 | E12: 147 | F12: 28
A13: ABA-1017 | B13: Azucar 1Kg | C13: Abarrotes Secos | D13: 10.96 | E13: 128 | F13: 520
A14: BEB-1012 | B14: Te Helado 2L | C14: Bebidas Pesadas | D14: 15.66 | E14: 72 | F14: 306
A15: PRO-1014 | B15: Edicion Limitada 6Pz | C15: Estacional Promo | D15: 5.27 | E15: 60 | F15: 129
A16: BOT-1014 | B16: Botana Mixta 350G | C16: Botanas Alto Volumen | D16: 3.92 | E16: 49 | F16: 98
A17: LAC-1002 | B17: Yogurt Bebible 900Ml | C17: Lacteos Perecederos | D17: 7.71 | E17: 101 | F17: 23
A18: BOT-1001 | B18: Cacahuates 60G | C18: Botanas Alto Volumen | D18: 6.95 | E18: 66 | F18: 95
A19: ABA-1001 | B19: Arroz 1Kg | C19: Abarrotes Secos | E19: 100 | F19: 512
A20: LAC-1007 | B20: Yogurt Bebible 900Ml | C20: Lacteos Perecederos | D20: 10.37 | E20: 100 | F20: 24
A21: PRO-1008 | B21: Edicion Especial Pack 12 | C21: Estacional Promo | D21: 11.98 | E21: 86 | F21: 123
A22: PRO-1013 | B22: Combo Fiesta 10Pz | C22: Estacional Promo | D22: 4.37 | E22: 58 | F22: 92
A23: LAC-1005 | B23: Crema 450Ml | C23: Lacteos Perecederos | D23: 8.94 | E23: 100 | F23: 17
A24: BOT-1013 | B24: Botana Mixta 200G | C24: Botanas Alto Volumen | D24: 4 | E24: 58 | F24: 112
A25: BOT-1015 | B25: Cacahuates 60G | C25: Botanas Alto Volumen | D25: 3.64 | E25: 62 | F25: 114
A26: ABA-1003 | B26: Avena 200G | C26: Abarrotes Secos | D26: 8.67 | E26: 124 | F26: 512
A27: LAC-1004 | B27: Yogurt Bebible 220Ml | C27: Lacteos Perecederos | D27: 11.45 | E27: 93 | F27: 16
A28: BEB-1021 | B28: Agua Mineral 1.5L | C28: Bebidas Pesadas | D28: 16.28 | E28: 90 | F28: 280
A29: BEB-1001 | B29: Agua Mineral 1.5L | C29: Bebidas Pesadas | D29: 19.18 | E29: 95 | F29: 208
A30: LAC-1001 | B30: Yogurt Griego 1000G | C30: Lacteos Perecederos | D30: 7.51 | E30: 83 | F30: 18
A31: PRO-1010 | B31: Edicion Especial Pack 6 | C31: Estacional Promo | D31: 7.76 | E31: 86 | F31: 112
... A56: BOT-1023 | B56: Botana Mixta 200G | C56: Botanas Alto Volumen | D56: 4.29 | E56: 44 | F56: 111
A57: BOT-1007 | B57: Cacahuates 210G | C57: Botanas Alto Volumen | E57: 49 | F57: 104
A58: LAC-1008 | B58: Yogurt Griego 500G | C58: Lacteos Perecederos | D58: 9.8 | E58: 83 | F58: 15
A59: BEB-1011 | B59: Te Helado 2L | C59: Bebidas Pesadas | D59: 23.39 | E59: 79 | F59: 329
A60: PRO-1000 | B60: Temporada Pack 6 | C60: Estacional Promo | D60: 12.51 | E60: 73 | F60: 75
A61: LAC-1013 | B61: Yogurt Bebible 220Ml | C61: Lacteos Perecederos | D61: 8.32 | E61: 98 | F61: 16
A62: ABA-1018 | B62: Azucar 1Kg | C62: Abarrotes Secos | D62: 11.43 | E62: 128 | F62: 530
A63: BEB-1006 | B63: Refresco Toronja 500Ml | C63: Bebidas Pesadas | D63: 17.18 | E63: 81 | F63: 293
A64: ABA-1005 | B64: Cereal 200G | C64: Abarrotes Secos | D64: 13.31 | E64: 89 | F64: 313
...

Sheet DRP_Engine
A1: DC | B1: Item_Code | C1: Current_Inventory | D1: Avg_Daily_Demand | E1: Demand_StdDev | F1: Lead_Time_Days | G1: Lead_Time_StdDev | H1: Safety_Stock | I1: Reorder_Point | J1: In_Transit_Qty | K1: Days_Cover | L1: Status
A2: CD-TOL | B2: PRO-1014 | C2: 2862 | D2: 395 | E2: 268.5 | F2: 2 | G2: 0.5 | H2: =IFERROR(1.65*SQRT(F2*E2^2 + D2^2*G2^2), "") -> 706.21301 | I2: =IFERROR(D2*F2 + H2, "") -> 1496.213 | J2: =SUMIFS(Transit_Clean[Quantity], Transit_Clean[Destination], A2, Transit_Clean[Item_Code], B2, Transit_Clean[SAP_Status], "In Transit") -> 0 | K2: =IFERROR(C2/D2, "") -> 7.2455696 | L2: {=_xlfn.IFS(C2<0,"DATO INVALIDO", C2+J2<I2,"PEDIR YA", C2<I2,"EN CAMINO OK", TRUE,"SANO")} -> SANO
A3: CD-CDMX | B3: BOT-1006 | C3: 3657 | D3: 408.6 | E3: 117.3 | F3: 0.7 | G3: 0.2 | H3: =IFERROR(1.65*SQRT(F3*E3^2 + D3^2*G3^2), "") -> 210.72032 | I3: =IFERROR(D3*F3 + H3, "") -> 496.74032 | J3: =SUMIFS(Transit_Clean[Quantity], Transit_Clean[Destination], A3, Transit_Clean[Item_Code], B3, Transit_Clean[SAP_Status], "In Transit") -> 0 | K3: =IFERROR(C3/D3, "") -> 8.9500734 | L3: {=_xlfn.IFS(C3<0,"DATO INVALIDO", C3+J3<I3,"PEDIR YA", C3<I3,"EN CAMINO OK", TRUE,"SANO")} -> SANO
A4: CD-VER | B4: BEB-1011 | C4: 4182 | E4: 63.7 | F4: 5 | G4: 0.9 | H4: =IFERROR(1.65*SQRT(F4*E4^2 + D4^2*G4^2), "") -> 235.02192 | I4: =IFERROR(D4*F4 + H4, "") -> 235.02192 | J4: =SUMIFS(Transit_Clean[Quantity], Transit_Clean[Destination], A4, Transit_Clean[Item_Code], B4, Transit_Clean[SAP_Status], "In Transit") -> 0 | K4: =IFERROR(C4/D4, "") | L4: {=_xlfn.IFS(C4<0,"DATO INVALIDO", C4+J4<I4,"PEDIR YA", C4<I4,"EN CAMINO OK", TRUE,"SANO")} -> SANO
A5: CD-TOL | B5: ABA-1007 | C5: 8913 | D5: 553.8 | E5: 67.5 | F5: 1.7 | G5: 0.5 | H5: =IFERROR(1.65*SQRT(F5*E5^2 + D5^2*G5^2), "") -> 479.40731 | I5: =IFERROR(D5*F5 + H5, "") -> 1420.8673 | J5: =SUMIFS(Transit_Clean[Quantity], Transit_Clean[Destination], A5, Transit_Clean[Item_Code], B5, Transit_Clean[SAP_Status], "In Transit") -> 0 | K5: =IFERROR(C5/D5, "") -> 16.094258 | L5: {=_xlfn.IFS(C5<0,"DATO INVALIDO", C5+J5<I5,"PEDIR YA", C5<I5,"EN CAMINO OK", TRUE,"SANO")} -> SANO
A6: CD-CDMX | B6: BEB-1000 | C6: 6474 | D6: 366.7 | E6: 43.8 | F6: 0.7 | G6: 0.2 | H6: =IFERROR(1.65*SQRT(F6*E6^2 + D6^2*G6^2), "") -> 135.27649 | I6: =IFERROR(D6*F6 + H6, "") -> 391.96649 | J6: =SUMIFS(Transit_Clean[Quantity], Transit_Clean[Destination], A6, Transit_Clean[Item_Code], B6, Transit_Clean[SAP_Status], "In Transit") -> 1239 | K6: =IFERROR(C6/D6, "") -> 17.654759 | L6: {=_xlfn.IFS(C6<0,"DATO INVALIDO", C6+J6<I6,"PEDIR YA", C6<I6,"EN CAMINO OK", TRUE,"SANO")} -> SANO
A7: CD-CDMX | B7: BOT-1013 | C7: 7599 | D7: 454.2 | E7: 93.4 | F7: 1.1 | G7: 0.2 | H7: =IFERROR(1.65*SQRT(F7*E7^2 + D7^2*G7^2), "") -> 220.43297 | I7: =IFERROR(D7*F7 + H7, "") -> 720.05297 | J7: =SUMIFS(Transit_Clean[Quantity], Transit_Clean[Destination], A7, Transit_Clean[Item_Code], B7, Transit_Clean[SAP_Status], "In Transit") -> 684 | K7: =IFERROR(C7/D7, "") -> 16.730515 | L7: {=_xlfn.IFS(C7<0,"DATO INVALIDO", C7+J7<I7,"PEDIR YA", C7<I7,"EN CAMINO OK", TRUE,"SANO")} -> SANO
A8: CD-VER | B8: BOT-1010 | C8: 6848 | D8: 784.3 | E8: 122.2 | F8: 3.1 | G8: 0.9 | H8: =IFERROR(1.65*SQRT(F8*E8^2 + D8^2*G8^2), "") -> 1217.5885 | I8: =IFERROR(D8*F8 + H8, "") -> 3648.9185 | J8: =SUMIFS(Transit_Clean[Quantity], Transit_Clean[Destination], A8, Transit_Clean[Item_Code], B8, Transit_Clean[SAP_Status], "In Transit") -> 1211 | K8: =IFERROR(C8/D8, "") -> 8.7313528 | L8: {=_xlfn.IFS(C8<0,"DATO INVALIDO", C8+J8<I8,"PEDIR YA", C8<I8,"EN CAMINO OK", TRUE,"SANO")} -> SANO
A9: CD-CHI | B9: LAC-1006 | C9: 1444 | D9: 209.7 | E9: 56.1 | F9: 3.1 | G9: 1 | H9: =IFERROR(1.65*SQRT(F9*E9^2 + D9^2*G9^2), "") -> 382.46716 | I9: =IFERROR(D9*F9 + H9, "") -> 1032.5372 | J9: =SUMIFS(Transit_Clean[Quantity], Transit_Clean[Destination], A9, Transit_Clean[Item_Code], B9, Transit_Clean[SAP_Status], "In Transit") -> 2495 | K9: =IFERROR(C9/D9, "") -> 6.8860277 | L9: {=_xlfn.IFS(C9<0,"DATO INVALIDO", C9+J9<I9,"PEDIR YA", C9<I9,"EN CAMINO OK", TRUE,"SANO")} -> SANO
A10: CD-VER | B10: BOT-1012 | C10: 16574 | D10: 948.9 | E10: 207.4 | F10: 0.9 | G10: 0.9 | H10: =IFERROR(1.65*SQRT(F10*E10^2 + D10^2*G10^2), "") -> 1446.0312 | I10: =IFERROR(D10*F10 + H10, "") -> 2300.0412 | J10: =SUMIFS(Transit_Clean[Quantity], Transit_Clean[Destination], A10, Transit_Clean[Item_Code], B10, Transit_Clean[SAP_Status], "In Transit") -> 1798 | K10: =IFERROR(C10/D10, "") -> 17.46654 | L10: {=_xlfn.IFS(C10<0,"DATO INVALIDO", C10+J10<I10,"PEDIR YA", C10<I10,"EN CAMINO OK", TRUE,"SANO")} -> SANO
A11: CD-PUE | B11: ABA-1007 | C11: 1422 | D11: 289.9 | E11: 31.2 | F11: 0.5 | G11: 0.3 | H11: =IFERROR(1.65*SQRT(F11*E11^2 + D11^2*G11^2), "") -> 148.04556 | I11: =IFERROR(D11*F11 + H11, "") -> 292.99556 | J11: =SUMIFS(Transit_Clean[Quantity], Transit_Clean[Destination], A11, Transit_Clean[Item_Code], B11, Transit_Clean[SAP_Status], "In Transit") -> 2569 | K11: =IFERROR(C11/D11, "") -> 4.9051397 | L11: {=_xlfn.IFS(C11<0,"DATO INVALIDO", C11+J11<I11,"PEDIR YA", C11<I11,"EN CAMINO OK", TRUE,"SANO")} -> SANO
A12: CD-CHI | B12: PRO-1001 | C12: 8663 | D12: 495.2 | E12: 204.3 | F12: 2.1 | G12: 1 | H12: =IFERROR(1.65*SQRT(F12*E12^2 + D12^2*G12^2), "") -> 951.97117 | I12: =IFERROR(D12*F12 + H12, "") -> 1991.8912 | J12: =SUMIFS(Transit_Clean[Quantity], Transit_Clean[Destination], A12, Transit_Clean[Item_Code], B12, Transit_Clean[SAP_Status], "In Transit") -> 0 | K12: =IFERROR(C12/D12, "") -> 17.493942 | L12: {=_xlfn.IFS(C12<0,"DATO INVALIDO", C12+J12<I12,"PEDIR YA", C12<I12,"EN CAMINO OK", TRUE,"SANO")} -> SANO
A13: CD-TIJ | B13: BOT-1016 | C13: 580 | D13: 800.5 | E13: 236.1 | F13: 3.4 | G13: 1.5 | H13: =IFERROR(1.65*SQRT(F13*E13^2 + D13^2*G13^2), "") -> 2107.4366 | I13: =IFERROR(D13*F13 + H13, "") -> 4829.1366 | J13: =SUMIFS(Transit_Clean[Quantity], Transit_Clean[Destination], A13, Transit_Clean[Item_Code], B13, Transit_Clean[SAP_Status], "In Transit") -> 0 | K13: =IFERROR(C13/D13, "") -> 0.72454716 | L13: {=_xlfn.IFS(C13<0,"DATO INVALIDO", C13+J13<I13,"PEDIR YA", C13<I13,"EN CAMINO OK", TRUE,"SANO")} -> PEDIR YA
A14: CD-PUE | B14: BOT-1001 | C14: 4706 | D14: 1097.7 | E14: 258.7 | F14: 0.9 | G14: 0.3 | H14: =IFERROR(1.65*SQRT(F14*E14^2 + D14^2*G14^2), "") -> 677.66245 | I14: =IFERROR(D14*F14 + H14, "") -> 1665.5924 | J14: =SUMIFS(Transit_Clean[Quantity], Transit_Clean[Destination], A14, Transit_Clean[Item_Code], B14, Transit_Clean[SAP_Status], "In Transit") -> 2599 | K14: =IFERROR(C14/D14, "") -> 4.2871459 | L14: {=_xlfn.IFS(C14<0,"DATO INVALIDO", C14+J14<I14,"PEDIR YA", C14<I14,"EN CAMINO OK", TRUE,"SANO")} -> SANO
A15: CD-PUE | B15: BOT-1010 | C15: 1583 | D15: 833.9 | E15: 188.9 | F15: 0.8 | G15: 0.3 | H15: =IFERROR(1.65*SQRT(F15*E15^2 + D15^2*G15^2), "") -> 498.10217 | I15: =IFERROR(D15*F15 + H15, "") -> 1165.2222 | J15: =SUMIFS(Transit_Clean[Quantity], Transit_Clean[Destination], A15, Transit_Clean[Item_Code], B15, Transit_Clean[SAP_Status], "In Transit") -> 0 | K15: =IFERROR(C15/D15, "") -> 1.8983091 | L15: {=_xlfn.IFS(C15<0,"DATO INVALIDO", C15+J15<I15,"PEDIR YA", C15<I15,"EN CAMINO OK", TRUE,"SANO")} -> SANO
A16: CD-QRO | B16: BEB-1015 | C16: 1077 | D16: 325.9 | E16: 33 | F16: 1.2 | G16: 0.4 | H16: =IFERROR(1.65*SQRT(F16*E16^2 + D16^2*G16^2), "") -> 223.21109 | I16: =IFERROR(D16*F16 + H16, "") -> 614.29109 | J16: =SUMIFS(Transit_Clean[Quantity], Transit_Clean[Destination], A16, Transit_Clean[Item_Code], B16, Transit_Clean[SAP_Status], "In Transit") -> 2207 | K16: =IFERROR(C16/D16, "") -> 3.3046947 | L16: {=_xlfn.IFS(C16<0,"DATO INVALIDO", C16+J16<I16,"PEDIR YA", C16<I16,"EN CAMINO OK", TRUE,"SANO")} -> SANO
... A37: CD-QRO | B37: ABA-1004 | C37: 1575 | D37: 188.3 | E37: 17.7 | F37: 1.8 | G37: 0.4 | H37: =IFERROR(1.65*SQRT(F37*E37^2 + D37^2*G37^2), "") -> 130.30848 | I37: =IFERROR(D37*F37 + H37, "") -> 469.24848 | J37: =SUMIFS(Transit_Clean[Quantity], Transit_Clean[Destination], A37, Transit_Clean[Item_Code], B37, Transit_Clean[SAP_Status], "In Transit") -> 1559 | K37: =IFERROR(C37/D37, "") -> 8.3643123 | L37: {=_xlfn.IFS(C37<0,"DATO INVALIDO", C37+J37<I37,"PEDIR YA", C37<I37,"EN CAMINO OK", TRUE,"SANO")} -> SANO
A38: CD-SAL | B38: LAC-1000 | D38: 334.9 | E38: 99.2 | F38: 1.7 | G38: 0.5 | H38: =IFERROR(1.65*SQRT(F38*E38^2 + D38^2*G38^2), "") -> 349.11672 | I38: =IFERROR(D38*F38 + H38, "") -> 918.44672 | J38: =SUMIFS(Transit_Clean[Quantity], Transit_Clean[Destination], A38, Transit_Clean[Item_Code], B38, Transit_Clean[SAP_Status], "In Transit") -> 0 | K38: =IFERROR(C38/D38, "") -> 0 | L38: {=_xlfn.IFS(C38<0,"DATO INVALIDO", C38+J38<I38,"PEDIR YA", C38<I38,"EN CAMINO OK", TRUE,"SANO")} -> PEDIR YA
A39: CD-MTY | B39: BOT-1003 | C39: 9638 | D39: 541.9 | E39: 88.2 | F39: 1.1 | G39: 0.3 | H39: =IFERROR(1.65*SQRT(F39*E39^2 + D39^2*G39^2), "") -> 308.62574 | I39: =IFERROR(D39*F39 + H39, "") -> 904.71574 | J39: =SUMIFS(Transit_Clean[Quantity], Transit_Clean[Destination], A39, Transit_Clean[Item_Code], B39, Transit_Clean[SAP_Status], "In Transit") -> 0 | K39: =IFERROR(C39/D39, "") -> 17.785569 | L39: {=_xlfn.IFS(C39<0,"DATO INVALIDO", C39+J39<I39,"PEDIR YA", C39<I39,"EN CAMINO OK", TRUE,"SANO")} -> SANO
A40: CD-CHI | B40: LAC-1010 | C40: 4103 | D40: 485.8 | E40: 198.2 | F40: 2.5 | G40: 1 | H40: =IFERROR(1.65*SQRT(F40*E40^2 + D40^2*G40^2), "") -> 953.87946 | I40: =IFERROR(D40*F40 + H40, "") -> 2168.3795 | J40: =SUMIFS(Transit_Clean[Quantity], Transit_Clean[Destination], A40, Transit_Clean[Item_Code], B40, Transit_Clean[SAP_Status], "In Transit") -> 1192 | K40: =IFERROR(C40/D40, "") -> 8.4458625 | L40: {=_xlfn.IFS(C40<0,"DATO INVALIDO", C40+J40<I40,"PEDIR YA", C40<I40,"EN CAMINO OK", TRUE,"SANO")} -> SANO
A41: CD-MOR | B41: BEB-1002 | C41: 2497 | D41: 162.4 | E41: 19.3 | F41: 1.7 | G41: 0.5 | H41: =IFERROR(1.65*SQRT(F41*E41^2 + D41^2*G41^2), "") -> 140.26624 | I41: =IFERROR(D41*F41 + H41, "") -> 416.34624 | J41: =SUMIFS(Transit_Clean[Quantity], Transit_Clean[Destination], A41, Transit_Clean[Item_Code], B41, Transit_Clean[SAP_Status], "In Transit") -> 0 | K41: =IFERROR(C41/D41, "") -> 15.375616 | L41: {=_xlfn.IFS(C41<0,"DATO INVALIDO", C41+J41<I41,"PEDIR YA", C41<I41,"EN CAMINO OK", TRUE,"SANO")} -> SANO
A42: CD-CDMX | B42: LAC-1008 | C42: 2440 | D42: 275.4 | E42: 102.8 | F42: 0.6 | G42: 0.2 | H42: =IFERROR(1.65*SQRT(F42*E42^2 + D42^2*G42^2), "") -> 159.75639 | I42: =IFERROR(D42*F42 + H42, "") -> 324.99639 | J42: =SUMIFS(Transit_Clean[Quantity], Transit_Clean[Destination], A42, Transit_Clean[Item_Code], B42, Transit_Clean[SAP_Status], "In Transit") -> 2199 | K42: =IFERROR(C42/D42, "") -> 8.8598402 | L42: {=_xlfn.IFS(C42<0,"DATO INVALIDO", C42+J42<I42,"PEDIR YA", C42<I42,"EN CAMINO OK", TRUE,"SANO")} -> SANO
A43: CD-QRO | B43: BOT-1014 | C43: 1048 | D43: 360.1 | E43: 85.6 | F43: 1.7 | G43: 0.4 | H43: =IFERROR(1.65*SQRT(F43*E43^2 + D43^2*G43^2), "") -> 300.66257 | I43: =IFERROR(D43*F43 + H43, "") -> 912.83257 | J43: =SUMIFS(Transit_Clean[Quantity], Transit_Clean[Destination], A43, Transit_Clean[Item_Code], B43, Transit_Clean[SAP_Status], "In Transit") -> 0 | K43: =IFERROR(C43/D43, "") -> 2.9103027 | L43: {=_xlfn.IFS(C43<0,"DATO INVALIDO", C43+J43<I43,"PEDIR YA", C43<I43,"EN CAMINO OK", TRUE,"SANO")} -> SANO
A44: CD-GDL | B44: PRO-1000 | C44: 3885 | D44: 394.7 | E44: 258.3 | F44: 0.5 | G44: 0.2 | H44: =IFERROR(1.65*SQRT(F44*E44^2 + D44^2*G44^2), "") -> 328.30841 | I44: =IFERROR(D44*F44 + H44, "") -> 525.65841 | J44: =SUMIFS(Transit_Clean[Quantity], Transit_Clean[Destination], A44, Transit_Clean[Item_Code], B44, Transit_Clean[SAP_Status], "In Transit") -> 0 | K44: =IFERROR(C44/D44, "") -> 9.8429187 | L44: {=_xlfn.IFS(C44<0,"DATO INVALIDO", C44+J44<I44,"PEDIR YA", C44<I44,"EN CAMINO OK", TRUE,"SANO")} -> SANO
A45: CD-QRO | B45: LAC-1008 | C45: 2600 | D45: 152.7 | E45: 51.4 | F45: 1.7 | G45: 0.4 | H45: =IFERROR(1.65*SQRT(F45*E45^2 + D45^2*G45^2), "") -> 149.61505 | I45: =IFERROR(D45*F45 + H45, "") -> 409.20505 | J45: =SUMIFS(Transit_Clean[Quantity], Transit_Clean[Destination], A45, Transit_Clean[Item_Code], B45, Transit_Clean[SAP_Status], "In Transit") -> 0 | K45: =IFERROR(C45/D45, "") -> 17.02685 | L45: {=_xlfn.IFS(C45<0,"DATO INVALIDO", C45+J45<I45,"PEDIR YA", C45<I45,"EN CAMINO OK", TRUE,"SANO")} -> SANO
A46: CD-CHI | B46: BOT-1010 | C46: 5685 | D46: 352.1 | E46: 103.1 | F46: 4.2 | G46: 1 | H46: =IFERROR(1.65*SQRT(F46*E46^2 + D46^2*G46^2), "") -> 677.54307 | I46: =IFERROR(D46*F46 + H46, "") -> 2156.3631 | J46: =SUMIFS(Transit_Clean[Quantity], Transit_Clean[Destination], A46, Transit_Clean[Item_Code], B46, Transit_Clean[SAP_Status], "In Transit") -> 602 | K46: =IFERROR(C46/D46, "") -> 16.145981 | L46: {=_xlfn.IFS(C46<0,"DATO INVALIDO", C46+J46<I46,"PEDIR YA", C46<I46,"EN CAMINO OK", TRUE,"SANO")} -> SANO
A47: CD-MER | B47: BOT-1016 | C47: 2068 | D47: 378.2 | E47: 89.2 | F47: 1.8 | G47: 1.3 | H47: =IFERROR(1.65*SQRT(F47*E47^2 + D47^2*G47^2), "") -> 834.92528 | I47: =IFERROR(D47*F47 + H47, "") -> 1515.6853 | J47: =SUMIFS(Transit_Clean[Quantity], Transit_Clean[Destination], A47, Transit_Clean[Item_Code], B47, Transit_Clean[SAP_Status], "In Transit") -> 0 | K47: =IFERROR(C47/D47, "") -> 5.4680063 | L47: {=_xlfn.IFS(C47<0,"DATO INVALIDO", C47+J47<I47,"PEDIR YA", C47<I47,"EN CAMINO OK", TRUE,"SANO")} -> SANO
A48: CD-SAL | B48: BOT-1009 | C48: 10536 | D48: 627 | E48: 160.4 | F48: 2 | G48: 0.5 | H48: =IFERROR(1.65*SQRT(F48*E48^2 + D48^2*G48^2), "") -> 638.48513 | I48: =IFERROR(D48*F48 + H48, "") -> 1892.4851 | J48: =SUMIFS(Transit_Clean[Quantity], Transit_Clean[Destination], A48, Transit_Clean[Item_Code], B48, Transit_Clean[SAP_Status], "In Transit") -> 0 | K48: =IFERROR(C48/D48, "") -> 16.803828 | L48: {=_xlfn.IFS(C48<0,"DATO INVALIDO", C48+J48<I48,"PEDIR YA", C48<I48,"EN CAMINO OK", TRUE,"SANO")} -> SANO
A49: CD-CAN | B49: ABA-1006 | C49: 6643 | D49: 463.7 | E49: 43.5 | F49: 7.7 | G49: 1.6 | H49: =IFERROR(1.65*SQRT(F49*E49^2 + D49^2*G49^2), "") -> 1240.2641 | I49: =IFERROR(D49*F49 + H49, "") -> 4810.7541 | J49: =SUMIFS(Transit_Clean[Quantity], Transit_Clean[Destination], A49, Transit_Clean[Item_Code], B49, Transit_Clean[SAP_Status], "In Transit") -> 0 | K49: =IFERROR(C49/D49, "") -> 14.326073 | L49: {=_xlfn.IFS(C49<0,"DATO INVALIDO", C49+J49<I49,"PEDIR YA", C49<I49,"EN CAMINO OK", TRUE,"SANO")} -> SANO
A50: CD-MTY | B50: LAC-1000 | C50: 3134 | D50: 370.7 | E50: 133.6 | F50: 1.3 | G50: 0.3 | H50: =IFERROR(1.65*SQRT(F50*E50^2 + D50^2*G50^2), "") -> 311.19591 | I50: =IFERROR(D50*F50 + H50, "") -> 793.10591 | J50: =SUMIFS(Transit_Clean[Quantity], Transit_Clean[Destination], A50, Transit_Clean[Item_Code], B50, Transit_Clean[SAP_Status], "In Transit") -> 0 | K50: =IFERROR(C50/D50, "") -> 8.4542757 | L50: {=_xlfn.IFS(C50<0,"DATO INVALIDO", C50+J50<I50,"PEDIR YA", C50<I50,"EN CAMINO OK", TRUE,"SANO")} -> SANO
